2025-05-16 09:34:32,491 ERROR scheduler Exception in Enqueue Events for Site library.test
Traceback (most recent call last):
  File "/home/limendo/frappe-bench/env/lib/python3.10/site-packages/pymysql/connections.py", line 782, in _read_bytes
    data = self._rfile.read(num_bytes)
  File "/usr/lib/python3.10/socket.py", line 705, in readinto
    return self._sock.recv_into(b)
ConnectionResetError: [Errno 104] Connection reset by peer

During handling of the above exception, another exception occurred:

Traceback (most recent call last):
  File "/home/limendo/frappe-bench/apps/frappe/frappe/utils/scheduler.py", line 99, in enqueue_events_for_site
    if is_scheduler_inactive():
  File "/home/limendo/frappe-bench/apps/frappe/frappe/utils/scheduler.py", line 143, in is_scheduler_inactive
    if is_scheduler_disabled(verbose=verbose):
  File "/home/limendo/frappe-bench/apps/frappe/frappe/utils/scheduler.py", line 156, in is_scheduler_disabled
    frappe.db.get_single_value("System Settings", "enable_scheduler")
  File "/home/limendo/frappe-bench/apps/frappe/frappe/database/database.py", line 837, in get_single_value
    ).run()
  File "/home/limendo/frappe-bench/apps/frappe/frappe/query_builder/utils.py", line 87, in execute_query
    result = frappe.db.sql(query, params, *args, **kwargs)  # nosemgrep
  File "/home/limendo/frappe-bench/apps/frappe/frappe/database/database.py", line 207, in sql
    self.connect()
  File "/home/limendo/frappe-bench/apps/frappe/frappe/database/database.py", line 112, in connect
    self._conn: "MariadbConnection" | "PostgresConnection" = self.get_connection()
  File "/home/limendo/frappe-bench/apps/frappe/frappe/database/mariadb/database.py", line 108, in get_connection
    conn = self._get_connection()
  File "/home/limendo/frappe-bench/apps/frappe/frappe/database/mariadb/database.py", line 114, in _get_connection
    return self.create_connection()
  File "/home/limendo/frappe-bench/apps/frappe/frappe/database/mariadb/database.py", line 117, in create_connection
    return pymysql.connect(**self.get_connection_settings())
  File "/home/limendo/frappe-bench/env/lib/python3.10/site-packages/pymysql/connections.py", line 361, in __init__
    self.connect()
  File "/home/limendo/frappe-bench/env/lib/python3.10/site-packages/pymysql/connections.py", line 669, in connect
    self._request_authentication()
  File "/home/limendo/frappe-bench/env/lib/python3.10/site-packages/pymysql/connections.py", line 957, in _request_authentication
    auth_packet = self._read_packet()
  File "/home/limendo/frappe-bench/env/lib/python3.10/site-packages/pymysql/connections.py", line 744, in _read_packet
    packet_header = self._read_bytes(4)
  File "/home/limendo/frappe-bench/env/lib/python3.10/site-packages/pymysql/connections.py", line 788, in _read_bytes
    raise err.OperationalError(
pymysql.err.OperationalError: (2013, 'Lost connection to MySQL server during query ([Errno 104] Connection reset by peer)')
2025-05-20 12:09:01,404 ERROR scheduler Exception in Enqueue Events for Site library.test
Traceback (most recent call last):
  File "/home/limendo/frappe-bench/env/lib/python3.10/site-packages/pymysql/connections.py", line 782, in _read_bytes
    data = self._rfile.read(num_bytes)
  File "/usr/lib/python3.10/socket.py", line 705, in readinto
    return self._sock.recv_into(b)
ConnectionResetError: [Errno 104] Connection reset by peer

During handling of the above exception, another exception occurred:

Traceback (most recent call last):
  File "/home/limendo/frappe-bench/apps/frappe/frappe/utils/scheduler.py", line 99, in enqueue_events_for_site
    if is_scheduler_inactive():
  File "/home/limendo/frappe-bench/apps/frappe/frappe/utils/scheduler.py", line 143, in is_scheduler_inactive
    if is_scheduler_disabled(verbose=verbose):
  File "/home/limendo/frappe-bench/apps/frappe/frappe/utils/scheduler.py", line 156, in is_scheduler_disabled
    frappe.db.get_single_value("System Settings", "enable_scheduler")
  File "/home/limendo/frappe-bench/apps/frappe/frappe/database/database.py", line 837, in get_single_value
    ).run()
  File "/home/limendo/frappe-bench/apps/frappe/frappe/query_builder/utils.py", line 87, in execute_query
    result = frappe.db.sql(query, params, *args, **kwargs)  # nosemgrep
  File "/home/limendo/frappe-bench/apps/frappe/frappe/database/database.py", line 207, in sql
    self.connect()
  File "/home/limendo/frappe-bench/apps/frappe/frappe/database/database.py", line 112, in connect
    self._conn: "MariadbConnection" | "PostgresConnection" = self.get_connection()
  File "/home/limendo/frappe-bench/apps/frappe/frappe/database/mariadb/database.py", line 108, in get_connection
    conn = self._get_connection()
  File "/home/limendo/frappe-bench/apps/frappe/frappe/database/mariadb/database.py", line 114, in _get_connection
    return self.create_connection()
  File "/home/limendo/frappe-bench/apps/frappe/frappe/database/mariadb/database.py", line 117, in create_connection
    return pymysql.connect(**self.get_connection_settings())
  File "/home/limendo/frappe-bench/env/lib/python3.10/site-packages/pymysql/connections.py", line 361, in __init__
    self.connect()
  File "/home/limendo/frappe-bench/env/lib/python3.10/site-packages/pymysql/connections.py", line 669, in connect
    self._request_authentication()
  File "/home/limendo/frappe-bench/env/lib/python3.10/site-packages/pymysql/connections.py", line 957, in _request_authentication
    auth_packet = self._read_packet()
  File "/home/limendo/frappe-bench/env/lib/python3.10/site-packages/pymysql/connections.py", line 744, in _read_packet
    packet_header = self._read_bytes(4)
  File "/home/limendo/frappe-bench/env/lib/python3.10/site-packages/pymysql/connections.py", line 788, in _read_bytes
    raise err.OperationalError(
pymysql.err.OperationalError: (2013, 'Lost connection to MySQL server during query ([Errno 104] Connection reset by peer)')
2025-05-20 12:15:00,199 ERROR scheduler Exception in Enqueue Events for Site library.test
Traceback (most recent call last):
  File "/home/limendo/frappe-bench/env/lib/python3.10/site-packages/pymysql/connections.py", line 806, in _write_bytes
    self._sock.sendall(data)
ConnectionResetError: [Errno 104] Connection reset by peer

During handling of the above exception, another exception occurred:

Traceback (most recent call last):
  File "/home/limendo/frappe-bench/apps/frappe/frappe/utils/scheduler.py", line 99, in enqueue_events_for_site
    if is_scheduler_inactive():
  File "/home/limendo/frappe-bench/apps/frappe/frappe/utils/scheduler.py", line 143, in is_scheduler_inactive
    if is_scheduler_disabled(verbose=verbose):
  File "/home/limendo/frappe-bench/apps/frappe/frappe/utils/scheduler.py", line 156, in is_scheduler_disabled
    frappe.db.get_single_value("System Settings", "enable_scheduler")
  File "/home/limendo/frappe-bench/apps/frappe/frappe/database/database.py", line 837, in get_single_value
    ).run()
  File "/home/limendo/frappe-bench/apps/frappe/frappe/query_builder/utils.py", line 87, in execute_query
    result = frappe.db.sql(query, params, *args, **kwargs)  # nosemgrep
  File "/home/limendo/frappe-bench/apps/frappe/frappe/database/database.py", line 207, in sql
    self.connect()
  File "/home/limendo/frappe-bench/apps/frappe/frappe/database/database.py", line 112, in connect
    self._conn: "MariadbConnection" | "PostgresConnection" = self.get_connection()
  File "/home/limendo/frappe-bench/apps/frappe/frappe/database/mariadb/database.py", line 108, in get_connection
    conn = self._get_connection()
  File "/home/limendo/frappe-bench/apps/frappe/frappe/database/mariadb/database.py", line 114, in _get_connection
    return self.create_connection()
  File "/home/limendo/frappe-bench/apps/frappe/frappe/database/mariadb/database.py", line 117, in create_connection
    return pymysql.connect(**self.get_connection_settings())
  File "/home/limendo/frappe-bench/env/lib/python3.10/site-packages/pymysql/connections.py", line 361, in __init__
    self.connect()
  File "/home/limendo/frappe-bench/env/lib/python3.10/site-packages/pymysql/connections.py", line 669, in connect
    self._request_authentication()
  File "/home/limendo/frappe-bench/env/lib/python3.10/site-packages/pymysql/connections.py", line 956, in _request_authentication
    self.write_packet(data)
  File "/home/limendo/frappe-bench/env/lib/python3.10/site-packages/pymysql/connections.py", line 732, in write_packet
    self._write_bytes(data)
  File "/home/limendo/frappe-bench/env/lib/python3.10/site-packages/pymysql/connections.py", line 809, in _write_bytes
    raise err.OperationalError(
pymysql.err.OperationalError: (2006, "MySQL server has gone away (ConnectionResetError(104, 'Connection reset by peer'))")
